Workbook

Sheet Summary
C2: Compliance Tool Kit (CTK)v1.4.4 - Verification Summary
C4: Windows - SBI Testing
C5: Test(s) Metrics | D5: With Mock | J5: With Device | Q5: Mock Details: - MOSIP mock SBI Note: Windows CTK with real devices testing is out of scope
D6: Auth | G6: Reg | J6: Auth | M6: Reg
D7: FP | E7: IRIS | F7: Face | G7: FP | H7: IRIS | I7: Face | J7: FP | K7: IRIS | L7: Face | M7: FP | N7: IRIS | O7: Face
C8: Total | D8: =COUNTIF('Windows-SBI'!E2:E492, "yes") -> 35 | E8: =COUNTIF('Windows-SBI'!C2:C492, "yes") -> 27 | F8: =COUNTIF('Windows-SBI'!D2:D492, "yes") -> 41 | G8: =COUNTIF('Windows-SBI'!H2:H492, "yes") -> 55 | H8: =COUNTIF('Windows-SBI'!F2:F492, "yes") -> 29 | I8: =COUNTIF('Windows-SBI'!G2:G492, "yes") -> 48 | J8: =COUNTIF('Windows-SBI'!E2:E492, "yes") -> 35 | K8: =COUNTIF('Windows-SBI'!C2:C492, "yes") -> 27 | L8: =COUNTIF('Windows-SBI'!D2:D492, "yes") -> 41 | M8: =COUNTIF('Windows-SBI'!H2:H492, "yes") -> 55 | N8: =COUNTIF('Windows-SBI'!F2:F492, "yes") -> 29 | O8: =COUNTIF('Windows-SBI'!G2:G492, "yes") -> 48
C9: Passed | D9: =COUNTIFS('Windows-SBI'!E1:E491, "yes", 'Windows-SBI'!X1:X491, "Pass") -> 35 | E9: =COUNTIFS('Windows-SBI'!C1:C491, "yes", 'Windows-SBI'!Z1:Z491, "Pass") -> 27 | F9: =COUNTIFS('Windows-SBI'!D1:D491, "yes", 'Windows-SBI'!Y1:Y491, "Pass") -> 41 | G9: =COUNTIFS('Windows-SBI'!H1:H491, "yes", 'Windows-SBI'!W1:W491, "Pass") -> 55 | H9: =COUNTIFS('Windows-SBI'!F1:F491, "yes", 'Windows-SBI'!U1:U491, "Pass") -> 29 | I9: =COUNTIFS('Windows-SBI'!G1:G491, "yes", 'Windows-SBI'!V1:V491, "Pass") -> 48 | J9: =COUNTIFS('Windows-SBI'!E1:E491, "yes", 'Windows-SBI'!R1:R491, "Pass") -> 0 | K9: =COUNTIFS('Windows-SBI'!C1:C491, "yes", 'Windows-SBI'!S1:S491, "Pass") -> 0 | L9: =COUNTIFS('Windows-SBI'!D1:D491, "yes", 'Windows-SBI'!T1:T491, "Pass") -> 0 | M9: =COUNTIFS('Windows-SBI'!H1:H491, "yes", 'Windows-SBI'!Q1:Q491, "Pass") -> 0 | N9: =COUNTIFS('Windows-SBI'!F1:F491, "yes", 'Windows-SBI'!O1:O491, "Pass") -> 0 | O9: =COUNTIFS('Windows-SBI'!G1:G491, "yes", 'Windows-SBI'!P1:P491, "Pass") -> 0
C10: Failed | D10: =COUNTIFS('Windows-SBI'!E1:E491, "yes", 'Windows-SBI'!X1:X491, "Fail") -> 0 | E10: =COUNTIFS('Windows-SBI'!C1:C491, "yes", 'Windows-SBI'!Z1:Z491, "Fail") -> 0 | F10: =COUNTIFS('Windows-SBI'!D1:D491, "yes", 'Windows-SBI'!Y1:Y491, "Fail") -> 0 | G10: =COUNTIFS('Windows-SBI'!H1:H491, "yes", 'Windows-SBI'!W1:W491, "Fail") -> 0 | H10: =COUNTIFS('Windows-SBI'!F1:F491, "yes", 'Windows-SBI'!U1:U491, "Fail") -> 0 | I10: =COUNTIFS('Windows-SBI'!G1:G491, "yes", 'Windows-SBI'!V1:V491, "Fail") -> 0 | J10: =COUNTIFS('Windows-SBI'!E1:E491, "yes", 'Windows-SBI'!R1:R491, "Fail") -> 0 | K10: =COUNTIFS('Windows-SBI'!C1:C491, "yes", 'Windows-SBI'!S1:S491, "Fail") -> 0 | L10: =COUNTIFS('Windows-SBI'!D1:D491, "yes", 'Windows-SBI'!T1:T491, "Fail") -> 0 | M10: =COUNTIFS('Windows-SBI'!H1:H491, "yes", 'Windows-SBI'!Q1:Q491, "Fail") -> 0 | N10: =COUNTIFS('Windows-SBI'!F1:F491, "yes", 'Windows-SBI'!O1:O491, "Fail") -> 0 | O10: =COUNTIFS('Windows-SBI'!G1:G491, "yes", 'Windows-SBI'!P1:P491, "Fail") -> 0
C11: Pending | D11: =COUNTIFS('Windows-SBI'!E1:E491, "yes", 'Windows-SBI'!X1:X491, "Pending") -> 0 | E11: =COUNTIFS('Windows-SBI'!C1:C491, "yes", 'Windows-SBI'!Z1:Z491, "Pending") -> 0 | F11: =COUNTIFS('Windows-SBI'!D1:D491, "yes", 'Windows-SBI'!Y1:Y491, "Pending") -> 0 | G11: =COUNTIFS('Windows-SBI'!H1:H491, "yes", 'Windows-SBI'!W1:W491, "Pending") -> 0 | H11: =COUNTIFS('Windows-SBI'!F1:F491, "yes", 'Windows-SBI'!U1:U491, "Pending") -> 0 | I11: =COUNTIFS('Windows-SBI'!G1:G491, "yes", 'Windows-SBI'!V1:V491, "Pending") -> 0 | J11: =COUNTIFS('Windows-SBI'!E1:E491, "yes", 'Windows-SBI'!R1:R491, "Pending") -> 0 | K11: =COUNTIFS('Windows-SBI'!C1:C491, "yes", 'Windows-SBI'!S1:S491, "Pending") -> 0 | L11: =COUNTIFS('Windows-SBI'!D1:D491, "yes", 'Windows-SBI'!T1:T491, "Pending") -> 0 | M11: =COUNTIFS('Windows-SBI'!H1:H491, "yes", 'Windows-SBI'!Q1:Q491, "Pending") -> 0 | N11: =COUNTIFS('Windows-SBI'!F1:F491, "yes", 'Windows-SBI'!O1:O491, "Pending") -> 0 | O11: =COUNTIFS('Windows-SBI'!G1:G491, "yes", 'Windows-SBI'!P1:P491, "Pending") -> 0
C12: N/A | D12: =COUNTIFS('Windows-SBI'!E1:E491, "yes", 'Windows-SBI'!X1:X491, "N/A") -> 0 | E12: =COUNTIFS('Windows-SBI'!C1:C491, "yes", 'Windows-SBI'!Z1:Z491, "N/A") -> 0 | F12: =COUNTIFS('Windows-SBI'!D1:D491, "yes", 'Windows-SBI'!Y1:Y491, "N/A") -> 0 | G12: =COUNTIFS('Windows-SBI'!H1:H491, "yes", 'Windows-SBI'!W1:W491, "N/A") -> 0 | H12: =COUNTIFS('Windows-SBI'!F1:F491, "yes", 'Windows-SBI'!U1:U491, "N/A") -> 0 | I12: =COUNTIFS('Windows-SBI'!G1:G491, "yes", 'Windows-SBI'!V1:V491, "N/A") -> 0 | J12: =COUNTIFS('Windows-SBI'!E1:E491, "yes", 'Windows-SBI'!R1:R491, "N/A") -> 35 | K12: =COUNTIFS('Windows-SBI'!C1:C491, "yes", 'Windows-SBI'!S1:S491, "N/A") -> 27 | L12: =COUNTIFS('Windows-SBI'!D1:D491, "yes", 'Windows-SBI'!T1:T491, "N/A") -> 41 | M12: =COUNTIFS('Windows-SBI'!H1:H491, "yes", 'Windows-SBI'!Q1:Q491, "N/A") -> 55 | N12: =COUNTIFS('Windows-SBI'!F1:F491, "yes", 'Windows-SBI'!O1:O491, "N/A") -> 29 | O12: =COUNTIFS('Windows-SBI'!G1:G491, "yes", 'Windows-SBI'!P1:P491, "N/A") -> 48
C13: Test Rate (%) | D13: =(SUM(D9:D10)/D8)*100 -> 100 | E13: =(SUM(E9:E10)/E8)*100 -> 100 | F13: =(SUM(F9:F10)/F8)*100 -> 100 | G13: =(SUM(G9:G10)/G8)*100 -> 100 | H13: =(SUM(H9:H10)/H8)*100 -> 100 | I13: =(SUM(I9:I10)/I8)*100 -> 100 | J13: =(SUM(J9:J10)/J8)*100 -> 0 | K13: =(SUM(K9:K10)/K8)*100 -> 0 | ... O13: =(SUM(O9:O10)/O8)*100 -> 0
C14: Pass Rate (%) | D14: =(D9/D8)*100 -> 100 | E14: =(E9/E8)*100 -> 100 | F14: =(F9/F8)*100 -> 100 | G14: =(G9/G8)*100 -> 100 | H14: =(H9/H8)*100 -> 100 | I14: =(I9/I8)*100 -> 100 | J14: =(J9/J8)*100 -> 0 | K14: =(K9/K8)*100 -> 0 | ... O14: =(O9/O8)*100 -> 0
C15: Android - SBI Testing
C16: Test(s) Metrics | D16: With Mock | J16: With Device | Q16: Mock Details: - MOSIP Android mock SBI Note: Android CTK with real devices testing is out of scope
D17: Auth | G17: Reg | J17: Auth | M17: Reg
D18: FP | E18: IRIS | F18: Face | G18: FP | H18: IRIS | I18: Face | J18: FP | K18: IRIS | L18: Face | M18: FP | N18: IRIS | O18: Face
C19: Total | D19: =COUNTIF('Android-SBI'!E2:E492, "yes") -> 35 | E19: =COUNTIF('Android-SBI'!C2:C492, "yes") -> 27 | F19: =COUNTIF('Android-SBI'!D2:D492, "yes") -> 41 | G19: =COUNTIF('Android-SBI'!H2:H492, "yes") -> 49 | H19: =COUNTIF('Android-SBI'!F2:F492, "yes") -> 26 | I19: =COUNTIF('Android-SBI'!G2:G492, "yes") -> 45 | J19: =COUNTIF('Android-SBI'!E2:E492, "yes") -> 35 | K19: =COUNTIF('Android-SBI'!C2:C492, "yes") -> 27 | L19: =COUNTIF('Android-SBI'!D2:D492, "yes") -> 41 | M19: =COUNTIF('Android-SBI'!H2:H492, "yes") -> 49 | N19: =COUNTIF('Android-SBI'!F2:F492, "yes") -> 26 | O19: =COUNTIF('Android-SBI'!G2:G492, "yes") -> 45
C20: Passed | D20: =COUNTIFS('Android-SBI'!E1:E491, "yes", 'Android-SBI'!X1:X491, "Pass") -> 35 | E20: =COUNTIFS('Android-SBI'!C1:C491, "yes", 'Android-SBI'!Z1:Z491, "Pass") -> 27 | F20: =COUNTIFS('Android-SBI'!D1:D491, "yes", 'Android-SBI'!Y1:Y491, "Pass") -> 41 | G20: =COUNTIFS('Android-SBI'!H1:H491, "yes", 'Android-SBI'!W1:W491, "Pass") -> 49 | H20: =COUNTIFS('Android-SBI'!F1:F491, "yes", 'Android-SBI'!U1:U491, "Pass") -> 26 | I20: =COUNTIFS('Android-SBI'!G1:G491, "yes", 'Android-SBI'!V1:V491, "Pass") -> 45 | J20: =COUNTIFS('Android-SBI'!E1:E491, "yes", 'Android-SBI'!R1:R491, "Pass") -> 0 | K20: =COUNTIFS('Android-SBI'!C1:C491, "yes", 'Android-SBI'!S1:S491, "Pass") -> 0 | L20: =COUNTIFS('Android-SBI'!D1:D491, "yes", 'Android-SBI'!T1:T491, "Pass") -> 0 | M20: =COUNTIFS('Android-SBI'!H1:H491, "yes", 'Android-SBI'!Q1:Q491, "Pass") -> 0 | N20: =COUNTIFS('Android-SBI'!F1:F491, "yes", 'Android-SBI'!O1:O491, "Pass") -> 0 | O20: =COUNTIFS('Android-SBI'!G1:G491, "yes", 'Android-SBI'!P1:P491, "Pass") -> 0
C21: Failed | D21: =COUNTIFS('Android-SBI'!E1:E491, "yes", 'Android-SBI'!X1:X491, "Fail") -> 0 | E21: =COUNTIFS('Android-SBI'!C1:C491, "yes", 'Android-SBI'!Z1:Z491, "Fail") -> 0 | F21: =COUNTIFS('Android-SBI'!D1:D491, "yes", 'Android-SBI'!Y1:Y491, "Fail") -> 0 | G21: =COUNTIFS('Android-SBI'!H1:H491, "yes", 'Android-SBI'!W1:W491, "Fail") -> 0 | H21: =COUNTIFS('Android-SBI'!F1:F491, "yes", 'Android-SBI'!U1:U491, "Fail") -> 0 | I21: =COUNTIFS('Android-SBI'!G1:G491, "yes", 'Android-SBI'!V1:V491, "Fail") -> 0 | J21: =COUNTIFS('Android-SBI'!E1:E491, "yes", 'Android-SBI'!R1:R491, "Fail") -> 0 | K21: =COUNTIFS('Android-SBI'!C1:C491, "yes", 'Android-SBI'!S1:S491, "Fail") -> 0 | L21: =COUNTIFS('Android-SBI'!D1:D491, "yes", 'Android-SBI'!T1:T491, "Fail") -> 0 | M21: =COUNTIFS('Android-SBI'!H1:H491, "yes", 'Android-SBI'!Q1:Q491, "Fail") -> 0 | N21: =COUNTIFS('Android-SBI'!F1:F491, "yes", 'Android-SBI'!O1:O491, "Fail") -> 0 | O21: =COUNTIFS('Android-SBI'!G1:G491, "yes", 'Android-SBI'!P1:P491, "fail") -> 0
C22: Pending | D22: =COUNTIFS('Android-SBI'!E1:E491, "yes", 'Android-SBI'!X1:X491, "Pending") -> 0 | E22: =COUNTIFS('Android-SBI'!C1:C491, "yes", 'Android-SBI'!Z1:Z491, "Pending") -> 0 | F22: =COUNTIFS('Android-SBI'!D1:D491, "yes", 'Android-SBI'!Y1:Y491, "Pending") -> 0 | G22: =COUNTIFS('Android-SBI'!H1:H491, "yes", 'Android-SBI'!W1:W491, "Pending") -> 0 | H22: =COUNTIFS('Android-SBI'!F1:F491, "yes", 'Android-SBI'!U1:U491, "Pending") -> 0 | I22: =COUNTIFS('Android-SBI'!G1:G491, "yes", 'Android-SBI'!V1:V491, "Pending") -> 0 | J22: =COUNTIFS('Android-SBI'!E1:E491, "yes", 'Android-SBI'!R1:R491, "Pending") -> 0 | K22: =COUNTIFS('Android-SBI'!C1:C491, "yes", 'Android-SBI'!S1:S491, "Pending") -> 0 | L22: =COUNTIFS('Android-SBI'!D1:D491, "yes", 'Android-SBI'!T1:T491, "Pending") -> 0 | M22: =COUNTIFS('Android-SBI'!H1:H491, "yes", 'Android-SBI'!Q1:Q491, "Pending") -> 0 | N22: =COUNTIFS('Android-SBI'!F1:F491, "yes", 'Android-SBI'!O1:O491, "Pending") -> 0 | O22: =COUNTIFS('Android-SBI'!G1:G491, "yes", 'Android-SBI'!P1:P491, "Pending") -> 0
C23: N/A | D23: =COUNTIFS('Android-SBI'!E1:E491, "yes", 'Android-SBI'!X1:X491, "N/A") -> 0 | E23: =COUNTIFS('Android-SBI'!C1:C491, "yes", 'Android-SBI'!Z1:Z491, "N/A") -> 0 | F23: =COUNTIFS('Android-SBI'!D1:D491, "yes", 'Android-SBI'!Y1:Y491, "N/A") -> 0 | G23: =COUNTIFS('Android-SBI'!H1:H491, "yes", 'Android-SBI'!W1:W491, "N/A") -> 0 | H23: =COUNTIFS('Android-SBI'!F1:F491, "yes", 'Android-SBI'!U1:U491, "N/A") -> 0 | I23: =COUNTIFS('Android-SBI'!G1:G491, "yes", 'Android-SBI'!V1:V491, "N/A") -> 0 | J23: =COUNTIFS('Android-SBI'!E1:E491, "yes", 'Android-SBI'!R1:R491, "N/A") -> 35 | K23: =COUNTIFS('Android-SBI'!C1:C491, "yes", 'Android-SBI'!S1:S491, "N/A") -> 27 | L23: =COUNTIFS('Android-SBI'!D1:D491, "yes", 'Android-SBI'!T1:T491, "N/A") -> 41 | M23: =COUNTIFS('Android-SBI'!H1:H491, "yes", 'Android-SBI'!Q1:Q491, "N/A") -> 49 | N23: =COUNTIFS('Android-SBI'!F1:F491, "yes", 'Android-SBI'!O1:O491, "N/A") -> 26 | O23: =COUNTIFS('Android-SBI'!G1:G491, "yes", 'Android-SBI'!P1:P491, "N/A") -> 45
C24: Test Rate (%) | D24: =(SUM(D20:D21)/D19)*100 -> 100 | E24: =(SUM(E20:E21)/E19)*100 -> 100 | F24: =(SUM(F20:F21)/F19)*100 -> 100 | G24: =(SUM(G20:G21)/G19)*100 -> 100 | H24: =(SUM(H20:H21)/H19)*100 -> 100 | I24: =(SUM(I20:I21)/I19)*100 -> 100 | J24: =(SUM(J20:J21)/J19)*100 -> 0 | K24: =(SUM(K20:K21)/K19)*100 -> 0 | ... O24: =(SUM(O20:O21)/O19)*100 -> 0
C25: Pass Rate (%) | D25: =(D20/D19)*100 -> 100 | E25: =(E20/E19)*100 -> 100 | F25: =(F20/F19)*100 -> 100 | G25: =(G20/G19)*100 -> 100 | H25: =(H20/H19)*100 -> 100 | I25: =(I20/I19)*100 -> 100 | J25: =(J20/J19)*100 -> 0 | K25: =(K20/K19)*100 -> 0 | ... O25: =(O20/O19)*100 -> 0
C26: SDK Testing - Windows
C27: Test(s) Metrics | D27: With Windows-SDK | Q27: Mock ''Windows-SDK'' Details: - MOSIP mock SDK 1.2.0.2-SNAPSHOT' 'Windows-SDK' Note: Segmentation out of scope Real Bio SDK testing is out of scope
D28: Mock | E28: Tech5 | F28: NPrime
C29: Total | D29: =COUNTA('Windows-SDK'!B2:B494) -> 65 | E29: =COUNTA('Windows-SDK'!B2:B494) -> 65 | F29: =COUNTA('Windows-SDK'!B2:B494) -> 65
C30: Passed | D30: =COUNTIF('Windows-SDK'!I2:I494, "Pass") -> 65 | E30: =COUNTIF('Windows-SDK'!H2:H494, "Pass") -> 0 | F30: =COUNTIF('Windows-SDK'!J2:J494, "Pass") -> 0
C31: Failed | D31: =COUNTIF('Windows-SDK'!I2:I494, "Fail") -> 0 | E31: =COUNTIF('Windows-SDK'!H7:H494, "Fail") -> 0 | F31: =COUNTIF('Windows-SDK'!J7:J494, "Fail") -> 0
C32: Pending | D32: =COUNTIF('Windows-SDK'!I2:I494, "Pending") -> 0 | E32: =COUNTIF('Windows-SDK'!H7:H494, "Pending") -> 0 | F32: =COUNTIF('Windows-SDK'!J2:J494, "Pending") -> 0
C33: N/A | D33: =COUNTIF('Windows-SDK'!I2:I494, "N/A") -> 0 | E33: =COUNTIF('Windows-SDK'!H2:H494, "N/A") -> 65 | F33: =COUNTIF('Windows-SDK'!J2:J494, "N/A") -> 65
C34: Test Rate (%) | D34: =(SUM(D30:D31)/D29)*100 -> 100 | E34: =(SUM(E30:E31)/E29)*100 -> 0 | F34: =(SUM(F30:F31)/F29)*100 -> 0
C35: Pass Rate (%) | D35: =(D30/D29)*100 -> 100 | E35: =(E30/E29)*100 -> 0 | F35: =(F30/F29)*100 -> 0
C36: ABIS Testing - Windows
C37: Test(s) Metrics | D37: With ABIS | Q37: Mock ABIS Details: - MOSIP mock ABIS Note: Real ABIS testing is out of scope
D38: Mock | E38: Real
C39: Total | D39: 29 | E39: 29
C40: Passed | D40: 28 | E40: 0
C41: Failed | D41: 0 | E41: 0
C42: Pending | D42: 0 | E42: 0
...

Sheet ABIS
A1: S.No | B1: Test Id | C1: Test Name | D1: Test Description | E1: Validator | F1: Mock ABIS | G1: Real ABIS | H1: Remarks
A2: 1 | B2: ABIS3000 | C2: Insert one person\"s biomterics in ABIS | D2: Insert one person\"s biomterics in ABIS | E2: SchemaValidator | F2: Pass | G2: N/A
A3: 2 | B3: ABIS3001 | C3: Insert two person\"s biomterics in ABIS | D3: Insert two person\"s biomterics in ABIS | E3: SchemaValidator | F3: Pass | G3: N/A
A4: 3 | B4: ABIS3002 | C4: Invalid Insert request structure | D4: Invalid Insert request - request json structure is invalid | E4: SchemaValidator ExpectedFailureReasonValidator | F4: Pass | G4: N/A
A5: 4 | B5: ABIS3003 | C5: Invalid Insert request - missing referenceId | D5: Invalid Insert request - missing referenceId | E5: SchemaValidator ExpectedFailureReasonValidator | F5: Pass | G5: N/A
A6: 5 | B6: ABIS3005 | C6: Unable to fetch biometric details using referenceURL | D6: Unable to fetch biometric details using referenceURL | E6: SchemaValidator ExpectedFailureReasonValidator | F6: Pass | G6: N/A
A7: 6 | B7: ABIS3006 | C7: Invalid Insert request - Invalid reference url | D7: Invalid Insert request - Invalid reference url | E7: SchemaValidator ExpectedFailureReasonValidator | F7: Pass | G7: N/A
A8: 7 | B8: ABIS3007 | C8: Invalid Insert request - missing reference URL | D8: Invalid Insert request - missing reference URL | E8: SchemaValidator ExpectedFailureReasonValidator | F8: Pass | G8: N/A
A9: 8 | B9: ABIS3008 | C9: Invalid Insert request - missing request time | D9: Invalid Insert request - missing request time | E9: SchemaValidator ExpectedFailureReasonValidator | F9: Pass | G9: N/A
A10: 9 | B10: ABIS3009 | C10: Invalid Insert request - referenceId already exists | D10: Invalid Insert request - referenceId already exists | E10: SchemaValidator ExpectedFailureReasonValidator | F10: Pass | G10: N/A
A11: 10 | B11: ABIS3010 | C11: Invalid Insert request - CBEFF has no data | D11: CBEFF has no data /No biometric available for deduplication | E11: SchemaValidator ExpectedFailureReasonValidator | F11: Pass | G11: N/A
A12: 11 | B12: ABIS3011 | C12: Invalid Insert request - invalid version | D12: Invalid Insert request - invalid version | E12: SchemaValidator ExpectedFailureReasonValidator | F12: Pass | G12: N/A
A13: 12 | B13: ABIS3012 | C13: Invalid Insert request - invalid id | D13: Invalid Insert request - invalid id | E13: SchemaValidator ExpectedFailureReasonValidator | F13: Pass | G13: N/A
... A17: 16 | B17: ABIS3016 | C17: Invalid Insert request - invalid data | D17: Invalid Insert request - invalid data | E17: SchemaValidator ExpectedFailureReasonValidator | F17: Pass | G17: N/A
A18: 17 | B18: ABIS3017 | C18: Invalid Insert request - CBEFF data decryption failure | D18: Invalid Insert request - CBEFF data decryption failure | E18: SchemaValidator ExpectedFailureReasonValidator | F18: N/A | G18: N/A | H18: N/A for mock
A19: 18 | B19: ABIS3018 | C19: Identify - duplicate found for the referenceId against gallery | D19: Insert same biometrics multiple times, then test if duplicate is found for the referenceId against gallery | E19: SchemaValidator IdentifyDuplicateFoundValidator ExpectedDuplicateCountValidator | F19: Pass | G19: N/A
A20: 19 | B20: ABIS3019 | C20: Invalid Identify request structure | D20: Invalid Identify request - request json structure is invalid | E20: SchemaValidator ExpectedFailureReasonValidator | F20: Pass | G20: N/A
A21: 20 | B21: ABIS3020 | C21: Invalid Identify request - missing referenceId | D21: Invalid Identify request - missing referenceId | E21: SchemaValidator ExpectedFailureReasonValidator | F21: Pass | G21: N/A
A22: 21 | B22: ABIS3022 | C22: Invalid Identify request - missing request time | D22: Invalid Identify request - missing request time | E22: SchemaValidator ExpectedFailureReasonValidator | F22: Pass | G22: N/A
A23: 22 | B23: ABIS3023 | C23: Invalid Identify request - invalid version | D23: Invalid Identify request - invalid version | E23: SchemaValidator ExpectedFailureReasonValidator | F23: Pass | G23: N/A
A24: 23 | B24: ABIS3024 | C24: Invalid Identify request - invalid id | D24: Invalid Identify request - invalid id | E24: SchemaValidator ExpectedFailureReasonValidator | F24: Pass | G24: N/A
A25: 24 | B25: ABIS3025 | C25: Invalid Identify request - invalid request time format | D25: Invalid Identify request - invalid request time format | E25: "SchemaValidator ExpectedFailureReasonValidator" | F25: Pass | G25: N/A
A26: 25 | B26: ABIS3026 | C26: Identify - duplicate found for the referenceId (gallery skipped). Clear the ABIS cache before running this testcase. | D26: Insert same biometrics twice, then test if duplicate is found for the referenceId, (gallery skipped) | E26: "SchemaValidator IdentifyDuplicateFoundValidator ExpectedDuplicateCountValidator" | F26: Pass | G26: N/A
A27: 26 | B27: ABIS3027 | C27: Identify - duplicate found for the referenceId against gallery - where referenceId's are inserted | D27: Insert same biometrics multiple times, then test if duplicate is found for the referenceId against gallery | E27: "SchemaValidator IdentifyDuplicateFoundValidator ExpectedDuplicateCountValidator" | F27: Pass | G27: N/A
A28: 27 | B28: ABIS3028 | C28: Identify - duplicate found for the referenceId against gallery - but the referenceId's are not inserted | D28: Insert biometrics once, then test if duplicate is found for the referenceId against gallery - but the referenceId's are not inserted | E28: "SchemaValidator ExpectedFailureReasonValidator" | F28: Pass | G28: N/A
A29: 28 | B29: ABIS3029 | C29: Identify - duplicate not found for the referenceId against gallery | D29: Identify - duplicate not found for the referenceId against gallery | E29: SchemaValidator ExpectedDuplicateCountValidator | F29: Pass | G29: N/A
A30: 29 | B30: ABIS3030 | C30: Verify if ABIS is not generating new tokens for every insert request | D30: Verify if ABIS is not generating new tokens for every insert request | E30: SchemaValidator ABISTokenValidator | F30: Pass | G30: N/A

Sheet Windows-SBI
A1: S.No | B1: Test Id | C1: Auth-Iris | D1: Auth-Face | E1: Auth-FP | F1: Reg Iris | G1: Reg Face | H1: Reg FP | I1: Test Name | J1: Test Description | K1: Validator | L1: Type | M1: STATUS | N1: Dev Comments | O1: Results (Reg Iris) | P1: Results (Reg Face) | Q1: Results (Reg FP) | R1: Results (Auth FP) | S1: Results (Auth IRIS) | T1: Results (Auth Face) | U1: Results (Mock - Reg Iris) | V1: Results (Mock - Reg Face) | W1: Results (Mock - Reg FP) | X1: Results (Mock - Auth-FP) | Y1: Results (Mock - Auth-Face) | Z1: Results (Mock - Auth_IRIS)
A2: 1 | B2: SBI1000 | C2: Yes | D2: Yes | E2: Yes | F2: Yes | G2: Yes | H2: Yes | I2: Discover device | J2: Discover device | K2: SchemaValidator SignatureValidator | M2: Available | O2: N/A | P2: N/A | Q2: N/A | R2: N/A | S2: N/A | T2: N/A | U2: Pass | V2: Pass | W2: Pass | X2: Pass | Y2: Pass | Z2: Pass
A3: 2 | B3: SBI1001 | C3: Yes | D3: Yes | E3: Yes | F3: Yes | G3: Yes | H3: Yes | I3: Device Info | J3: Device Info | K3: SchemaValidator SignatureValidator | M3: Available | O3: N/A | P3: N/A | Q3: N/A | R3: N/A | S3: N/A | T3: N/A | U3: Pass | V3: Pass | W3: Pass | X3: Pass | Y3: Pass | Z3: Pass
A4: 3 | B4: SBI1002 | C4: No | D4: No | E4: No | F4: No | G4: No | H4: Yes | I4: Registration capture - Left Slab | J4: Registration capture - Left Slap | K4: SchemaValidator ResponseMismatchValidator SignatureValidator | L4: ResponseMismatchValidator | M4: Available | O4: N/A | P4: N/A | Q4: N/A | R4: N/A | S4: N/A | T4: N/A | U4: N/A | V4: N/A | W4: Pass | X4: N/A | Y4: N/A | Z4: N/A
A5: 4 | B5: SBI1003 | C5: No | D5: No | E5: No | F5: No | G5: No | H5: Yes | I5: Registration capture - Left Slab - One Exception | J5: Registration capture - Left Slap - One Exception | K5: SchemaValidator ResponseMismatchValidator SignatureValidator | L5: ResponseMismatchValidator | M5: Available | O5: N/A | P5: N/A | Q5: N/A | R5: N/A | S5: N/A | T5: N/A | U5: N/A | V5: N/A | W5: Pass | X5: N/A | Y5: N/A | Z5: N/A
A6: 5 | B6: SBI1004 | C6: No | D6: No | E6: No | F6: No | G6: No | H6: Yes | I6: Registration capture - Right Slab | J6: Registration capture - Right Slap | K6: SchemaValidator ResponseMismatchValidator SignatureValidator | L6: ResponseMismatchValidator | M6: Available | O6: N/A | P6: N/A | Q6: N/A | R6: N/A | S6: N/A | T6: N/A | U6: N/A | V6: N/A | W6: Pass | X6: N/A | Y6: N/A | Z6: N/A
A7: 6 | B7: SBI1005 | C7: No | D7: No | E7: No | F7: No | G7: No | H7: Yes | I7: Registration capture - Right Slab - Two Exception | J7: Registration capture - Right Slap - Two Exception | K7: SchemaValidator ResponseMismatchValidator SignatureValidator | L7: ResponseMismatchValidator | M7: Available | O7: N/A | P7: N/A | Q7: N/A | R7: N/A | S7: N/A | T7: N/A | U7: N/A | V7: N/A | W7: Pass | X7: N/A | Y7: N/A | Z7: N/A
A8: 7 | B8: SBI1006 | C8: No | D8: No | E8: No | F8: No | G8: No | H8: Yes | I8: Registration capture - Two Thumbs | J8: Registration capture - Two Thumbs | K8: SchemaValidator ResponseMismatchValidator SignatureValidator | L8: ResponseMismatchValidator | M8: Available | O8: N/A | P8: N/A | Q8: N/A | R8: N/A | S8: N/A | T8: N/A | U8: N/A | V8: N/A | W8: Pass | X8: N/A | Y8: N/A | Z8: N/A
A9: 8 | B9: SBI1007 | C9: No | D9: No | E9: No | F9: No | G9: No | H9: Yes | I9: Registration capture - Two Thumbs - One Exception | J9: Registration capture - Two Thumbs - One Exception | K9: SchemaValidator ResponseMismatchValidator SignatureValidator | L9: ResponseMismatchValidator | M9: Available | O9: N/A | P9: N/A | Q9: N/A | R9: N/A | S9: N/A | T9: N/A | U9: N/A | V9: N/A | W9: Pass | X9: N/A | Y9: N/A | Z9: N/A
A10: 9 | B10: SBI1008 | C10: No | D10: No | E10: No | F10: No | G10: No | H10: Yes | I10: Registration capture - Two Thumbs - Both Exception | J10: Registration capture - Two Thumbs - Both Exception | K10: SchemaValidator | M10: Available | O10: N/A | P10: N/A | Q10: N/A | R10: N/A | S10: N/A | T10: N/A | U10: N/A | V10: N/A | W10: Pass | X10: N/A | Y10: N/A | Z10: N/A
A11: 10 | B11: SBI1009 | C11: No | D11: No | E11: No | F11: Yes | G11: No | H11: No | I11: Registration capture - Double Iris | J11: Registration capture - Double Iris | K11: SchemaValidator ResponseMismatchValidator SignatureValidator | L11: ResponseMismatchValidator | M11: Available | O11: N/A | P11: N/A | Q11: N/A | R11: N/A | S11: N/A | T11: N/A | U11: Pass | V11: N/A | W11: N/A | X11: N/A | Y11: N/A | Z11: N/A
A12: 11 | B12: SBI1010 | C12: No | D12: No | E12: No | F12: Yes | G12: No | H12: No | I12: Registration capture - Double Iris - One Exception | J12: Registration capture - Double Iris - One Exception | K12: SchemaValidator ResponseMismatchValidator SignatureValidator | L12: ResponseMismatchValidator | M12: Available | O12: N/A | P12: N/A | Q12: N/A | R12: N/A | S12: N/A | T12: N/A | U12: Pass | V12: N/A | W12: N/A | X12: N/A | Y12: N/A | Z12: N/A
A13: 12 | B13: SBI1011 | C13: No | D13: No | E13: No | F13: Yes | G13: No | H13: No | I13: Registration capture - Double Iris - Both Exception | J13: Registration capture - Double Iris - Both Exception | K13: SchemaValidator | M13: Available | O13: N/A | P13: N/A | Q13: N/A | R13: N/A | S13: N/A | T13: N/A | U13: Pass | V13: N/A | W13: N/A | X13: N/A | Y13: N/A | Z13: N/A
A14: 13 | B14: SBI1012 | C14: No | D14: No | E14: No | F14: No | G14: Yes | H14: No | I14: Registration capture - Face | J14: Registration capture - Face | K14: SchemaValidator SignatureValidator ResponseMismatchValidator | L14: ResponseMismatchValidator | M14: Available | O14: N/A | P14: N/A | Q14: N/A | R14: N/A | S14: N/A | T14: N/A | U14: N/A | V14: Pass | W14: N/A | X14: N/A | Y14: N/A | Z14: N/A
A15: 14 | B15: SBI1013 | C15: No | D15: No | E15: No | F15: No | G15: Yes | H15: No | I15: Registration capture - Exception Photo | J15: Registration capture - Exception Photo | K15: SchemaValidator SignatureValidator | L15: ResponseMismatchValidator | M15: Available | O15: N/A | P15: N/A | Q15: N/A | R15: N/A | S15: N/A | T15: N/A | U15: N/A | V15: Pass | W15: N/A | X15: N/A | Y15: N/A | Z15: N/A
A16: 15 | B16: SBI1014 | C16: No | D16: Yes | E16: No | F16: No | G16: No | H16: No | I16: Auth capture - Face | J16: Auth capture - Face | K16: SchemaValidator ResponseMismatchValidator SignatureValidator | L16: ResponseMismatchValidator | M16: Available | O16: N/A | P16: N/A | Q16: N/A | R16: N/A | S16: N/A | T16: N/A | U16: N/A | V16: N/A | W16: N/A | X16: N/A | Y16: Pass | Z16: N/A
A17: 16 | B17: SBI1015 | C17: Yes | D17: No | E17: No | F17: No | G17: No | H17: No | I17: Auth capture - Single Iris - Unknown Iris | J17: Auth capture - Single Iris - Unknown Iris | K17: SchemaValidator ResponseMismatchValidator SignatureValidator | L17: ResponseMismatchValidator | M17: Available | O17: N/A | P17: N/A | Q17: N/A | R17: N/A | S17: N/A | T17: N/A | U17: N/A | V17: N/A | W17: N/A | X17: N/A | Y17: N/A | Z17: Pass
A18: 17 | B18: SBI1016 | C18: Yes | D18: No | E18: No | F18: No | G18: No | H18: No | I18: Auth capture - Single Iris - Left Iris | J18: Auth capture - Single Iris - Left Iris | K18: SchemaValidator ResponseMismatchValidator SignatureValidator | L18: ResponseMismatchValidator | M18: Available | O18: N/A | P18: N/A | Q18: N/A | R18: N/A | S18: N/A | T18: N/A | U18: N/A | V18: N/A | W18: N/A | X18: N/A | Y18: N/A | Z18: Pass
A19: 18 | B19: SBI1017 | C19: Yes | D19: No | E19: No | F19: No | G19: No | H19: No | I19: Auth capture - Single Iris - Right Iris | J19: Auth capture - Single Iris - Right Iris | K19: SchemaValidator ResponseMismatchValidator SignatureValidator | L19: ResponseMismatchValidator | M19: Available | O19: N/A | P19: N/A | Q19: N/A | R19: N/A | S19: N/A | T19: N/A | U19: N/A | V19: N/A | W19: N/A | X19: N/A | Y19: N/A | Z19: Pass
A20: 19 | B20: SBI1018 | C20: No | D20: No | E20: Yes | F20: No | G20: No | H20: No | I20: Auth capture - Unknown Finger | J20: Auth capture - Unknown Finger | K20: SchemaValidator ResponseMismatchValidator SignatureValidator | L20: ResponseMismatchValidator | M20: Available | O20: N/A | P20: N/A | Q20: N/A | R20: N/A | S20: N/A | T20: N/A | U20: N/A | V20: N/A | W20: N/A | X20: Pass | Y20: N/A | Z20: N/A
A21: 20 | B21: SBI1019 | C21: No | D21: No | E21: Yes | F21: No | G21: No | H21: No | I21: Auth capture -Two Unknown Finger | J21: Auth capture - Two Unknown Finger | K21: SchemaValidator ResponseMismatchValidator SignatureValidator | L21: ResponseMismatchValidator | M21: Available | O21: N/A | P21: N/A | Q21: N/A | R21: N/A | S21: N/A | T21: N/A | U21: N/A | V21: N/A | W21: N/A | X21: Pass | Y21: N/A | Z21: N/A
A22: 21 | B22: SBI1020 | C22: No | D22: No | E22: Yes | F22: No | G22: No | H22: No | I22: Auth capture - LeftIndex Finger | J22: Auth capture - LeftIndex Finger | K22: SchemaValidator ResponseMismatchValidator SignatureValidator | L22: ResponseMismatchValidator | M22: Available | O22: N/A | P22: N/A | Q22: N/A | R22: N/A | S22: N/A | T22: N/A | U22: N/A | V22: N/A | W22: N/A | X22: Pass | Y22: N/A | Z22: N/A
A23: 22 | B23: SBI1021 | C23: No | D23: No | E23: Yes | F23: No | G23: No | H23: No | I23: Auth capture - Two Finger | J23: Auth capture - Two Finger | K23: SchemaValidator ResponseMismatchValidator SignatureValidator | L23: ResponseMismatchValidator | M23: Available | O23: N/A | P23: N/A | Q23: N/A | R23: N/A | S23: N/A | T23: N/A | U23: N/A | V23: N/A | W23: N/A | X23: Pass | Y23: N/A | Z23: N/A
A24: 23 | B24: SBI1022 | C24: No | D24: No | E24: No | F24: No | G24: No | H24: Yes | I24: Registration capture - Key Rotation - Left Slap | J24: Registration capture - Key Rotation - Left Slap | K24: KeyRotationValidator | L24: Key Rotation | M24: Available | O24: N/A | P24: N/A | Q24: N/A | R24: N/A | S24: N/A | T24: N/A | U24: N/A | V24: N/A | W24: Pass | X24: N/A | Y24: N/A | Z24: N/A
A25: 24 | B25: SBI1023 | C25: Yes | D25: No | E25: No | F25: No | G25: No | H25: No | I25: Auth capture -Key Rotation - Single Iris - Left Iris | J25: Auth capture - Single Iris - Left Iris - Key Rotation | K25: KeyRotationValidator | L25: Key Rotation | M25: Available | O25: N/A | P25: N/A | Q25: N/A | R25: N/A | S25: N/A | T25: N/A | U25: N/A | V25: N/A | W25: N/A | X25: N/A | Y25: N/A | Z25: Pass
... A27: 26 | B27: SBI1025 | C27: No | D27: Yes | E27: No | F27: No | G27: No | H27: No | I27: Auth capture - Face - Key Rotation | J27: Auth capture - Face - Key Rotation | K27: KeyRotationValidator | L27: Key Rotation | M27: Available | O27: N/A | P27: N/A | Q27: N/A | R27: N/A | S27: N/A | T27: N/A | U27: N/A | V27: N/A | W27: N/A | X27: N/A | Y27: Pass | Z27: N/A
A28: 27 | B28: SBI1026 | C28: Yes | D28: Yes | E28: Yes | F28: Yes | G28: Yes | H28: Yes | I28: Check Device Status - Ready | J28: Check Device Status - Ready | K28: KeyRotationValidator | M28: Available | O28: N/A | P28: N/A | Q28: N/A | R28: N/A | S28: N/A | T28: N/A | U28: Pass | V28: Pass | W28: Pass | X28: Pass | Y28: Pass | Z28: Pass
A29: 28 | B29: SBI1027 | C29: Yes | D29: Yes | E29: Yes | F29: Yes | G29: Yes | H29: Yes | I29: Check Device Status - Busy | J29: Check Device Status - Busy | K29: SchemaValidator | L29: Device Status | M29: Available | O29: N/A | P29: N/A | Q29: N/A | R29: N/A | S29: N/A | T29: N/A | U29: Pass | V29: Pass | W29: Pass | X29: Pass | Y29: Pass | Z29: Pass
A30: 29 | B30: SBI1028 | C30: Yes | D30: Yes | E30: Yes | F30: Yes | G30: Yes | H30: Yes | I30: Check Device Status - Not Ready | J30: Check Device Status - Not Ready | K30: SchemaValidator | L30: Device Status | M30: Available | O30: N/A | P30: N/A | Q30: N/A | R30: N/A | S30: N/A | T30: N/A | U30: Pass | V30: Pass | W30: Pass | X30: Pass | Y30: Pass | Z30: Pass
A31: 30 | B31: SBI1029 | C31: Yes | D31: Yes | E31: Yes | F31: Yes | G31: Yes | H31: Yes | I31: Check Device Status - Not Registered | J31: Check Device Status - Not Registered | K31: SchemaValidator | L31: Device Status | M31: Available | O31: N/A | P31: N/A | Q31: N/A | R31: N/A | S31: N/A | T31: N/A | U31: Pass | V31: Pass | W31: Pass | X31: Pass | Y31: Pass | Z31: Pass
A32: 31 | B32: SBI1030 | C32: No | D32: No | E32: Yes | F32: No | G32: No | H32: No | I32: Auth capture - Fingerprint - Bio Count Mismatch | J32: Auth capture - Fingerprint - Bio Count Mismatch | K32: SchemaValidator | M32: Available | O32: N/A | P32: N/A | Q32: N/A | R32: N/A | S32: N/A | T32: N/A | U32: N/A | V32: N/A | W32: N/A | X32: Pass | Y32: N/A | Z32: N/A
A33: 32 | B33: SBI1031 | C33: Yes | D33: No | E33: No | F33: No | G33: No | H33: No | I33: Auth capture - Iris - Bio Count Mismatch | J33: Auth capture - Iris - Bio Count Mismatch | K33: SchemaValidator | M33: Available | O33: N/A | P33: N/A | Q33: N/A | R33: N/A | S33: N/A | T33: N/A | U33: N/A | V33: N/A | W33: N/A | X33: N/A | Y33: N/A | Z33: Pass
A34: 33 | B34: SBI1032 | C34: No | D34: Yes | E34: No | F34: No | G34: No | H34: No | I34: Auth capture - Face - Bio Count Mismatch | J34: Auth capture - Face - Bio Count Mismatch | K34: SchemaValidator | M34: Available | O34: N/A | P34: N/A | Q34: N/A | R34: N/A | S34: N/A | T34: N/A | U34: N/A | V34: N/A | W34: N/A | X34: N/A | Y34: Pass | Z34: N/A
A35: 34 | B35: SBI1033 | C35: No | D35: No | E35: No | F35: No | G35: No | H35: Yes | I35: Registration capture - Left Slap - Bio Count Mismatch | J35: Registration capture - Left Slap - Bio Count Mismatch | K35: SchemaValidator | M35: Available | O35: N/A | P35: N/A | Q35: N/A | R35: N/A | S35: N/A | T35: N/A | U35: N/A | V35: N/A | W35: Pass | X35: N/A | Y35: N/A | Z35: N/A
A36: 35 | B36: SBI1034 | C36: No | D36: No | E36: No | F36: No | G36: No | H36: Yes | I36: Registration capture - Right Slap - Bio Count Mismatch | J36: Registration capture - Right Slap - Bio Count Mismatch | K36: SchemaValidator | M36: Available | O36: N/A | P36: N/A | Q36: N/A | R36: N/A | S36: N/A | T36: N/A | U36: N/A | V36: N/A | W36: Pass | X36: N/A | Y36: N/A | Z36: N/A
A37: 36 | B37: SBI1035 | C37: No | D37: No | E37: No | F37: No | G37: No | H37: Yes | I37: Registration capture - Two Thumbs - Bio Count Mismatch | J37: Registration capture - Two Thumbs - Bio Count Mismatch | K37: SchemaValidator | M37: Available | O37: N/A | P37: N/A | Q37: N/A | R37: N/A | S37: N/A | T37: N/A | U37: N/A | V37: N/A | W37: Pass | X37: N/A | Y37: N/A | Z37: N/A
A38: 37 | B38: SBI1036 | C38: No | D38: No | E38: No | F38: Yes | G38: No | H38: No | I38: Registration capture - Left iris - Bio Count Mismatch | J38: Registration capture - Left iris - Bio Count Mismatch | K38: SchemaValidator | M38: Available | O38: N/A | P38: N/A | Q38: N/A | R38: N/A | S38: N/A | T38: N/A | U38: Pass | V38: N/A | W38: N/A | X38: N/A | Y38: N/A | Z38: N/A
A39: 38 | B39: SBI1037 | C39: No | D39: No | E39: No | F39: Yes | G39: No | H39: No | I39: Registration capture - Right Iris - Bio Count Mismatch | J39: Registration capture - Right Iris - Bio Count Mismatch | K39: SchemaValidator | M39: Available | O39: N/A | P39: N/A | Q39: N/A | R39: N/A | S39: N/A | T39: N/A | U39: Pass | V39: N/A | W39: N/A | X39: N/A | Y39: N/A | Z39: N/A
A40: 39 | B40: SBI1038 | C40: No | D40: No | E40: No | F40: Yes | G40: No | H40: No | I40: Registration capture - Both Iris - Bio Count Mismatch | J40: Registration capture - Both Iris - Bio Count Mismatch | K40: SchemaValidator | M40: Available | O40: N/A | P40: N/A | Q40: N/A | R40: N/A | S40: N/A | T40: N/A | U40: Pass | V40: N/A | W40: N/A | X40: N/A | Y40: N/A | Z40: N/A
A41: 40 | B41: SBI1039 | C41: No | D41: No | E41: No | F41: No | G41: Yes | H41: No | I41: Registration capture - Face - Bio Count Mismatch | J41: Registration capture - Face - Bio Count Mismatch | K41: SchemaValidator | M41: Available | O41: N/A | P41: N/A | Q41: N/A | R41: N/A | S41: N/A | T41: N/A | U41: N/A | V41: Pass | W41: N/A | X41: N/A | Y41: N/A | Z41: N/A
...

Sheet Windows-SDK
A1: S.No | B1: Test Id | C1: Test Name | D1: Synthetic testdata possible? | E1: Test Description | F1: Validator | G1: STATUS | H1: Real SDK (Tech5) | I1: Mock SDK | J1: Real SDK (NPrime)
A2: 1 | B2: SDK2000 | C2: Init Test | D2: N/A | E2: Initialise Bio SDK Services | F2: SchemaValidator | G2: Available | H2: N/A | I2: Pass | J2: N/A
A3: 2 | B3: SDK2001 | C3: Good face quality | D3: Yes | E3: 1. This testcase checks the biomterics for face to be of good quality.<br>2. Add the appropriate probe.xml | F3: SchemaValidator QualityCheckValidator | G3: Available | H3: N/A | I3: Pass | J3: N/A
A4: 3 | B4: SDK2002 | C4: Bad face quality | D4: Yes | E4: Bad face quality | F4: SchemaValidator QualityCheckValidator | G4: Available | H4: N/A | I4: Pass | J4: N/A
A5: 4 | B5: SDK2003 | C5: Invalid face data for quality check | D5: Yes | E5: Invalid face data for quality check | F5: SchemaValidator QualityCheckInvalidDataValidator | G5: Available | H5: N/A | I5: Pass | J5: N/A
A6: 5 | B6: SDK2004 | C6: No face data for quality check | D6: Yes | E6: No face data for quality check | F6: SchemaValidator QualityCheckNoDataValidator | G6: Available | H6: N/A | I6: Pass | J6: N/A
A7: 6 | B7: SDK2005 | C7: Bad finger quality | D7: Yes | E7: Bad finger quality | F7: SchemaValidator QualityCheckValidator | G7: Available | H7: N/A | I7: Pass | J7: N/A
A8: 7 | B8: SDK2006 | C8: Good finger quality | D8: Yes | E8: Good finger quality | F8: SchemaValidator QualityCheckValidator | G8: Available | H8: N/A | I8: Pass | J8: N/A
A9: 8 | B9: SDK2007 | C9: Invalid finger data for quality check | D9: Yes | E9: Invalid finger data for quality check | F9: SchemaValidator QualityCheckInvalidDataValidator | G9: Available | H9: N/A | I9: Pass | J9: N/A
A10: 9 | B10: SDK2008 | C10: No finger data for quality check | D10: Yes | E10: No finger data for quality check | F10: SchemaValidator QualityCheckNoDataValidator | G10: Available | H10: N/A | I10: Pass | J10: N/A
A11: 10 | B11: SDK2009 | C11: Bad iris quality | D11: Not Available | E11: Bad iris quality | F11: SchemaValidator QualityCheckValidator | G11: Available | H11: N/A | I11: Pass | J11: N/A
A12: 11 | B12: SDK2010 | C12: Good iris quality | D12: Not Available | E12: Good iris quality | F12: SchemaValidator QualityCheckValidator | G12: Available | H12: N/A | I12: Pass | J12: N/A
A13: 12 | B13: SDK2011 | C13: Invalid iris data for quality check | D13: Not Available | E13: Invalid iris data for quality check | F13: SchemaValidator QualityCheckInvalidDataValidator | G13: Available | H13: N/A | I13: Pass | J13: N/A
... A66: 67 | B66: SDK2075 | C66: Iris convert no input failure | D66: Not Available | E66: Iris convert no input failure | F66: SchemaValidator ConvertNoInputDataValidator | G66: Available | H66: N/A | I66: Pass | J66: N/A

Sheet Android-SBI
A1: . | B1: Test Id | C1: Auth-Iris | D1: Auth-Face | E1: Auth-FP | F1: Reg Iris | G1: Reg Face | H1: Reg FP | I1: Test Name | J1: Test Description | K1: Validator | L1: Type | M1: STATUS | N1: Dev Comments | O1: Results (Reg Iris) | P1: Results (Reg Face) | Q1: Results (Reg FP) | R1: Results (Auth FP) | S1: Results (Auth IRIS) | T1: Results (Auth Face) | U1: Results (Mock - Reg Iris) | V1: Results (Mock - Reg Face) | W1: Results (Mock - Reg FP) | X1: Results (Mock - Auth-FP) | Y1: Results (Mock - Auth-Face) | Z1: Results (Mock - Auth_IRIS) | AA1: Android
A2: 1 | B2: SBI1000 | C2: Yes | D2: Yes | E2: Yes | F2: Yes | G2: Yes | H2: Yes | I2: Discover device | J2: This testcase will perform device discovery for the selected device. | K2: SchemaValidator SignatureValidator | M2: Available | O2: N/A | P2: N/A | Q2: N/A | R2: N/A | S2: N/A | T2: N/A | U2: Pass | V2: Pass | W2: Pass | X2: Pass | Y2: Pass | Z2: Pass | AA2: Yes
A3: 2 | B3: SBI1001 | C3: Yes | D3: Yes | E3: Yes | F3: Yes | G3: Yes | H3: Yes | I3: Device Info | J3: This testcase will validate the device info for the selected device including trust validation. | K3: SchemaValidator SignatureValidator | M3: Available | O3: N/A | P3: N/A | Q3: N/A | R3: N/A | S3: N/A | T3: N/A | U3: Pass | V3: Pass | W3: Pass | X3: Pass | Y3: Pass | Z3: Pass | AA3: Yes
A4: 3 | B4: SBI1002 | C4: No | D4: No | E4: No | F4: No | G4: No | H4: Yes | I4: Registration capture - Left Slab | J4: This testcase is to check if Registration Capture for Left Slap from the device is valid or not. | K4: SchemaValidator ResponseMismatchValidator SignatureValidator | L4: ResponseMismatchValidator | M4: Available | N4: ResponseMismatchValidator newly added available in 1.0.0-b2 | O4: N/A | P4: N/A | Q4: N/A | R4: N/A | S4: N/A | T4: N/A | U4: N/A | V4: N/A | W4: Pass | X4: N/A | Y4: N/A | Z4: N/A | AA4: Yes
A5: 4 | B5: SBI1003 | C5: No | D5: No | E5: No | F5: No | G5: No | H5: Yes | I5: Registration capture - Left Slab - One Exception | J5: 1. This testcase is to check if Registration Capture for Left Slap from the device is valid or not.<br> 2. Please place your left slap <b>except left ring finger</b> on the device. | K5: SchemaValidator ResponseMismatchValidator SignatureValidator | L5: ResponseMismatchValidator | M5: Available | N5: ResponseMismatchValidator newly added available in 1.0.0-b2 | O5: N/A | P5: N/A | Q5: N/A | R5: N/A | S5: N/A | T5: N/A | U5: N/A | V5: N/A | W5: Pass | X5: N/A | Y5: N/A | Z5: N/A | AA5: Yes
A6: 5 | B6: SBI1004 | C6: No | D6: No | E6: No | F6: No | G6: No | H6: Yes | I6: Registration capture - Right Slab | J6: Valid Registration capture Request for Slap scanner type | K6: SchemaValidator ResponseMismatchValidator SignatureValidator | L6: ResponseMismatchValidator | M6: Available | N6: ResponseMismatchValidator newly added available in 1.0.0-b2 | O6: N/A | P6: N/A | Q6: N/A | R6: N/A | S6: N/A | T6: N/A | U6: N/A | V6: N/A | W6: Pass | X6: N/A | Y6: N/A | Z6: N/A | AA6: Yes
A7: 6 | B7: SBI1005 | C7: No | D7: No | E7: No | F7: No | G7: No | H7: Yes | I7: Registration capture - Right Slab - Two Exception | J7: Valid Registration capture Request for slap device type with right slap except right ring finger and right little finger | K7: SchemaValidator ResponseMismatchValidator SignatureValidator | L7: ResponseMismatchValidator | M7: Available | N7: ResponseMismatchValidator newly added available in 1.0.0-b2 | O7: N/A | P7: N/A | Q7: N/A | R7: N/A | S7: N/A | T7: N/A | U7: N/A | V7: N/A | W7: Pass | X7: N/A | Y7: N/A | Z7: N/A | AA7: Yes
A8: 7 | B8: SBI1006 | C8: No | D8: No | E8: No | F8: No | G8: No | H8: Yes | I8: Registration capture - Two Thumbs | J8: Valid Registration capture Request for Slap scanner type | K8: SchemaValidator ResponseMismatchValidator SignatureValidator | L8: ResponseMismatchValidator | M8: Available | N8: ResponseMismatchValidator newly added available in 1.0.0-b2 | O8: N/A | P8: N/A | Q8: N/A | R8: N/A | S8: N/A | T8: N/A | U8: N/A | V8: N/A | W8: Pass | X8: N/A | Y8: N/A | Z8: N/A | AA8: Yes
A9: 8 | B9: SBI1007 | C9: No | D9: No | E9: No | F9: No | G9: No | H9: Yes | I9: Registration capture - Two Thumbs - One Exception | J9: Valid Registration capture Request for slap device type with two thumbs except left thumb finger | K9: SchemaValidator ResponseMismatchValidator SignatureValidator | L9: ResponseMismatchValidator | M9: Available | N9: ResponseMismatchValidator newly added available in 1.0.0-b2 | O9: N/A | P9: N/A | Q9: N/A | R9: N/A | S9: N/A | T9: N/A | U9: N/A | V9: N/A | W9: Pass | X9: N/A | Y9: N/A | Z9: N/A | AA9: Yes
A10: 9 | B10: SBI1008 | C10: No | D10: No | E10: No | F10: No | G10: No | H10: Yes | I10: Registration capture - Two Thumbs - Both Exception | J10: Valid Registration capture Request for slap device type with two thumbs except right thumb finger and left thumb finger | K10: SchemaValidator | M10: Available | O10: N/A | P10: N/A | Q10: N/A | R10: N/A | S10: N/A | T10: N/A | U10: N/A | V10: N/A | W10: Pass | X10: N/A | Y10: N/A | Z10: N/A | AA10: Yes
A11: 10 | B11: SBI1009 | C11: No | D11: No | E11: No | F11: Yes | G11: No | H11: No | I11: Registration capture - Double Iris | J11: Valid Registration capture Request | K11: SchemaValidator ResponseMismatchValidator SignatureValidator | L11: ResponseMismatchValidator | M11: Available | N11: ResponseMismatchValidator newly added available in 1.0.0-b2 | O11: N/A | P11: N/A | Q11: N/A | R11: N/A | S11: N/A | T11: N/A | U11: Pass | V11: N/A | W11: N/A | X11: N/A | Y11: N/A | Z11: N/A | AA11: Yes
A12: 11 | B12: SBI1010 | C12: No | D12: No | E12: No | F12: Yes | G12: No | H12: No | I12: Registration capture - Double Iris - One Exception | J12: Valid Registration capture Request for Double iris device type except left iris | K12: SchemaValidator ResponseMismatchValidator SignatureValidator | L12: ResponseMismatchValidator | M12: Available | N12: ResponseMismatchValidator newly added available in 1.0.0-b2 | O12: N/A | P12: N/A | Q12: N/A | R12: N/A | S12: N/A | T12: N/A | U12: Pass | V12: N/A | W12: N/A | X12: N/A | Y12: N/A | Z12: N/A | AA12: Yes
A13: 12 | B13: SBI1011 | C13: No | D13: No | E13: No | F13: Yes | G13: No | H13: No | I13: Registration capture - Double Iris - Both Exception | J13: Valid Registration capture Request for Double iris device type except left iris and right iris | K13: SchemaValidator | M13: Available | O13: N/A | P13: N/A | Q13: N/A | R13: N/A | S13: N/A | T13: N/A | U13: Pass | V13: N/A | W13: N/A | X13: N/A | Y13: N/A | Z13: N/A | AA13: Yes
A14: 13 | B14: SBI1012 | C14: No | D14: No | E14: No | F14: No | G14: Yes | H14: No | I14: Registration capture - Face | J14: Valid Registration capture Request only for Face | K14: SchemaValidator SignatureValidator ResponseMismatchValidator | L14: ResponseMismatchValidator | M14: Available | N14: ResponseMismatchValidator newly added available in 1.0.0-b2 | O14: N/A | P14: N/A | Q14: N/A | R14: N/A | S14: N/A | T14: N/A | U14: N/A | V14: Pass | W14: N/A | X14: N/A | Y14: N/A | Z14: N/A | AA14: Yes
A15: 14 | B15: SBI1013 | C15: No | D15: No | E15: No | F15: No | G15: Yes | H15: No | I15: Registration capture - Exception Photo | J15: Valid Registration capture Request for Face device type exception value left little finger or any will give Exception photo | K15: SchemaValidator SignatureValidator | L15: ResponseMismatchValidator | M15: Available | N15: ResponseMismatchValidator newly added available in 1.0.0-b2 | O15: N/A | P15: N/A | Q15: N/A | R15: N/A | S15: N/A | T15: N/A | U15: N/A | V15: Pass | W15: N/A | X15: N/A | Y15: N/A | Z15: N/A | AA15: Yes
A16: 15 | B16: SBI1014 | C16: No | D16: Yes | E16: No | F16: No | G16: No | H16: No | I16: Auth capture - Face | J16: Valid Auth capture Request only for Face | K16: SchemaValidator ResponseMismatchValidator SignatureValidator | L16: ResponseMismatchValidator | M16: Available | N16: ResponseMismatchValidator newly added available in 1.0.0-b2 | O16: N/A | P16: N/A | Q16: N/A | R16: N/A | S16: N/A | T16: N/A | U16: N/A | V16: N/A | W16: N/A | X16: N/A | Y16: Pass | Z16: N/A | AA16: Yes
A17: 16 | B17: SBI1015 | C17: Yes | D17: No | E17: No | F17: No | G17: No | H17: No | I17: Auth capture - Single Iris - Unknown Iris | J17: Valid Auth capture Request for Unknown iris | K17: SchemaValidator ResponseMismatchValidator SignatureValidator | L17: ResponseMismatchValidator | M17: Available | N17: ResponseMismatchValidator newly added available in 1.0.0-b2 | O17: N/A | P17: N/A | Q17: N/A | R17: N/A | S17: N/A | T17: N/A | U17: N/A | V17: N/A | W17: N/A | X17: N/A | Y17: N/A | Z17: Pass | AA17: Yes
A18: 17 | B18: SBI1016 | C18: Yes | D18: No | E18: No | F18: No | G18: No | H18: No | I18: Auth capture - Single Iris - Left Iris | J18: Valid Auth capture Request for Left iris | K18: SchemaValidator ResponseMismatchValidator SignatureValidator | L18: ResponseMismatchValidator | M18: Available | N18: ResponseMismatchValidator newly added available in 1.0.0-b2 | O18: N/A | P18: N/A | Q18: N/A | R18: N/A | S18: N/A | T18: N/A | U18: N/A | V18: N/A | W18: N/A | X18: N/A | Y18: N/A | Z18: Pass | AA18: Yes
A19: 18 | B19: SBI1017 | C19: Yes | D19: No | E19: No | F19: No | G19: No | H19: No | I19: Auth capture - Single Iris - Right Iris | J19: Valid Auth capture Request for Right iris | K19: SchemaValidator ResponseMismatchValidator SignatureValidator | L19: ResponseMismatchValidator | M19: Available | N19: ResponseMismatchValidator newly added available in 1.0.0-b2 | O19: N/A | P19: N/A | Q19: N/A | R19: N/A | S19: N/A | T19: N/A | U19: N/A | V19: N/A | W19: N/A | X19: N/A | Y19: N/A | Z19: Pass | AA19: Yes
A20: 19 | B20: SBI1018 | C20: No | D20: No | E20: Yes | F20: No | G20: No | H20: No | I20: Auth capture - Unknown Finger | J20: Valid Auth capture Request for Unknown Finger | K20: SchemaValidator ResponseMismatchValidator SignatureValidator | L20: ResponseMismatchValidator | M20: Available | N20: ResponseMismatchValidator newly added available in 1.0.0-b2 | O20: N/A | P20: N/A | Q20: N/A | R20: N/A | S20: N/A | T20: N/A | U20: N/A | V20: N/A | W20: N/A | X20: Pass | Y20: N/A | Z20: N/A | AA20: Yes
A21: 20 | B21: SBI1019 | C21: No | D21: No | E21: Yes | F21: No | G21: No | H21: No | I21: Auth capture -Two Unknown Finger | J21: Valid Auth capture Request for Two Unknown Finger | K21: SchemaValidator ResponseMismatchValidator SignatureValidator | L21: ResponseMismatchValidator | M21: Available | N21: ResponseMismatchValidator newly added available in 1.0.0-b2 | O21: N/A | P21: N/A | Q21: N/A | R21: N/A | S21: N/A | T21: N/A | U21: N/A | V21: N/A | W21: N/A | X21: Pass | Y21: N/A | Z21: N/A | AA21: Yes
A22: 21 | B22: SBI1020 | C22: No | D22: No | E22: Yes | F22: No | G22: No | H22: No | I22: Auth capture - LeftIndex Finger | J22: Valid Auth capture Request for LeftIndex Finger | K22: SchemaValidator ResponseMismatchValidator SignatureValidator | L22: ResponseMismatchValidator | M22: Available | N22: ResponseMismatchValidator newly added available in 1.0.0-b2 | O22: N/A | P22: N/A | Q22: N/A | R22: N/A | S22: N/A | T22: N/A | U22: N/A | V22: N/A | W22: N/A | X22: Pass | Y22: N/A | Z22: N/A | AA22: Yes
A23: 22 | B23: SBI1021 | C23: No | D23: No | E23: Yes | F23: No | G23: No | H23: No | I23: Auth capture - Two Finger | J23: Valid Auth capture Request for Two Finger | K23: SchemaValidator ResponseMismatchValidator SignatureValidator | L23: ResponseMismatchValidator | M23: Available | N23: ResponseMismatchValidator newly added available in 1.0.0-b2 | O23: N/A | P23: N/A | Q23: N/A | R23: N/A | S23: N/A | T23: N/A | U23: N/A | V23: N/A | W23: N/A | X23: Pass | Y23: N/A | Z23: N/A | AA23: Yes
A24: 23 | B24: SBI1022 | C24: No | D24: No | E24: No | F24: No | G24: No | H24: Yes | I24: Registration capture - Key Rotation - Left Slap | J24: Test for device key rotation | K24: KeyRotationValidator | L24: Key Rotation | M24: Available | O24: N/A | P24: N/A | Q24: N/A | R24: N/A | S24: N/A | T24: N/A | U24: N/A | V24: N/A | W24: Pass | X24: N/A | Y24: N/A | Z24: N/A | AA24: Yes
A25: 24 | B25: SBI1023 | C25: Yes | D25: No | E25: No | F25: No | G25: No | H25: No | I25: Auth capture -Key Rotation - Single Iris - Left Iris | J25: Test for device key rotation | K25: KeyRotationValidator | L25: Key Rotation | M25: Available | O25: N/A | P25: N/A | Q25: N/A | R25: N/A | S25: N/A | T25: N/A | U25: N/A | V25: N/A | W25: N/A | X25: N/A | Y25: N/A | Z25: Pass | AA25: Yes
A26: 25 | B26: SBI1024 | C26: No | D26: No | E26: Yes | F26: No | G26: No | H26: No | I26: Auth capture - Key Rotation - LeftIndex Finger | J26: Test for device key rotation | K26: KeyRotationValidator | L26: Key Rotation | M26: Available | O26: N/A | P26: N/A | Q26: N/A | R26: N/A | S26: N/A | T26: N/A | U26: N/A | V26: N/A | W26: N/A | X26: Pass | Y26: N/A | Z26: N/A | AA26: Yes
A27: 26 | B27: SBI1025 | C27: No | D27: Yes | E27: No | F27: No | G27: No | H27: No | I27: Auth capture - Face - Key Rotation | J27: Test for device key rotation | K27: KeyRotationValidator | L27: Key Rotation | M27: Available | O27: N/A | P27: N/A | Q27: N/A | R27: N/A | S27: N/A | T27: N/A | U27: N/A | V27: N/A | W27: N/A | X27: N/A | Y27: Pass | Z27: N/A | AA27: Yes
A28: 27 | B28: SBI1026 | C28: Yes | D28: Yes | E28: Yes | F28: Yes | G28: Yes | H28: Yes | I28: Check Device Status - Ready | J28: Test to validate Device Info interface for a device that is in Ready state | K28: SchemaValidator SignatureValidator | L28: Device Status | M28: Available | O28: N/A | P28: N/A | Q28: N/A | R28: N/A | S28: N/A | T28: N/A | U28: Pass | V28: Pass | W28: Pass | X28: Pass | Y28: Pass | Z28: Pass | AA28: Yes
A29: 28 | B29: SBI1027 | C29: Yes | D29: Yes | E29: Yes | F29: Yes | G29: Yes | H29: Yes | I29: Check Device Status - Busy | J29: Test to validate if the device is in Busy state | K29: SchemaValidator SignatureValidator | L29: Device Status | M29: Available | O29: N/A | P29: N/A | Q29: N/A | R29: N/A | S29: N/A | T29: N/A | U29: Pass | V29: Pass | W29: Pass | X29: Pass | Y29: Pass | Z29: Pass | AA29: Yes
A30: 29 | B30: SBI1028 | C30: Yes | D30: Yes | E30: Yes | F30: Yes | G30: Yes | H30: Yes | I30: Check Device Status - Not Ready | J30: Test to validate if the device is in Not Ready state | K30: SchemaValidator SignatureValidator | L30: Device Status | M30: Available | O30: N/A | P30: N/A | Q30: N/A | R30: N/A | S30: N/A | T30: N/A | U30: Pass | V30: Pass | W30: Pass | X30: Pass | Y30: Pass | Z30: Pass | AA30: Yes
A31: 30 | B31: SBI1029 | C31: Yes | D31: Yes | E31: Yes | F31: Yes | G31: Yes | H31: Yes | I31: Check Device Status - Not Registered | J31: Test to validate if the device is in Not Registered state | K31: SchemaValidator SignatureValidator | L31: Device Status | M31: Available | O31: N/A | P31: N/A | Q31: N/A | R31: N/A | S31: N/A | T31: N/A | U31: Pass | V31: Pass | W31: Pass | X31: Pass | Y31: Pass | Z31: Pass | AA31: Yes
A32: 31 | B32: SBI1030 | C32: No | D32: No | E32: Yes | F32: No | G32: No | H32: No | I32: Auth capture - Fingerprint - Bio Count Mismatch | J32: Test to validate bio count mismatch for auth fingerprint device | K32: SchemaValidator | M32: Available | O32: N/A | P32: N/A | Q32: N/A | R32: N/A | S32: N/A | T32: N/A | U32: N/A | V32: N/A | W32: N/A | X32: Pass | Y32: N/A | Z32: N/A | AA32: Yes
A33: 32 | B33: SBI1031 | C33: Yes | D33: No | E33: No | F33: No | G33: No | H33: No | I33: Auth capture - Iris - Bio Count Mismatch | J33: Test to validate bio count mismatch for auth iris device | K33: SchemaValidator | M33: Available | O33: N/A | P33: N/A | Q33: N/A | R33: N/A | S33: N/A | T33: N/A | U33: N/A | V33: N/A | W33: N/A | X33: N/A | Y33: N/A | Z33: Pass | AA33: Yes
A34: 33 | B34: SBI1032 | C34: No | D34: Yes | E34: No | F34: No | G34: No | H34: No | I34: Auth capture - Face - Bio Count Mismatch | J34: Test to validate bio count mismatch for face | K34: SchemaValidator | M34: Available | O34: N/A | P34: N/A | Q34: N/A | R34: N/A | S34: N/A | T34: N/A | U34: N/A | V34: N/A | W34: N/A | X34: N/A | Y34: Pass | Z34: N/A | AA34: Yes
A35: 34 | B35: SBI1033 | C35: No | D35: No | E35: No | F35: No | G35: No | H35: Yes | I35: Registration capture - Left Slap - Bio Count Mismatch | J35: Test to validate bio count mismatch for registration left slap | K35: SchemaValidator | M35: Available | O35: N/A | P35: N/A | Q35: N/A | R35: N/A | S35: N/A | T35: N/A | U35: N/A | V35: N/A | W35: Pass | X35: N/A | Y35: N/A | Z35: N/A | AA35: Yes
A36: 35 | B36: SBI1034 | C36: No | D36: No | E36: No | F36: No | G36: No | H36: Yes | I36: Registration capture - Right Slap - Bio Count Mismatch | J36: Test to validate bio count mismatch for registration right slap | K36: SchemaValidator | M36: Available | O36: N/A | P36: N/A | Q36: N/A | R36: N/A | S36: N/A | T36: N/A | U36: N/A | V36: N/A | W36: Pass | X36: N/A | Y36: N/A | Z36: N/A | AA36: Yes
A37: 36 | B37: SBI1035 | C37: No | D37: No | E37: No | F37: No | G37: No | H37: Yes | I37: Registration capture - Two Thumbs - Bio Count Mismatch | J37: Test to validate bio count mismatch for registration thumbs | K37: SchemaValidator | M37: Available | O37: N/A | P37: N/A | Q37: N/A | R37: N/A | S37: N/A | T37: N/A | U37: N/A | V37: N/A | W37: Pass | X37: N/A | Y37: N/A | Z37: N/A | AA37: Yes
A38: 37 | B38: SBI1036 | C38: No | D38: No | E38: No | F38: Yes | G38: No | H38: No | I38: Registration capture - Left iris - Bio Count Mismatch | J38: Test to validate bio count mismatch for registration left iris | K38: SchemaValidator | M38: Available | O38: N/A | P38: N/A | Q38: N/A | R38: N/A | S38: N/A | T38: N/A | U38: Pass | V38: N/A | W38: N/A | X38: N/A | Y38: N/A | Z38: N/A | AA38: Yes
A39: 38 | B39: SBI1037 | C39: No | D39: No | E39: No | F39: Yes | G39: No | H39: No | I39: Registration capture - Right Iris - Bio Count Mismatch | J39: Test to validate bio count mismatch for registration right iris | K39: SchemaValidator | M39: Available | O39: N/A | P39: N/A | Q39: N/A | R39: N/A | S39: N/A | T39: N/A | U39: Pass | V39: N/A | W39: N/A | X39: N/A | Y39: N/A | Z39: N/A | AA39: Yes
A40: 39 | B40: SBI1038 | C40: No | D40: No | E40: No | F40: Yes | G40: No | H40: No | I40: Registration capture - Both Iris - Bio Count Mismatch | J40: Test to validate bio count mismatch for registration both iris | K40: SchemaValidator | M40: Available | O40: N/A | P40: N/A | Q40: N/A | R40: N/A | S40: N/A | T40: N/A | U40: Pass | V40: N/A | W40: N/A | X40: N/A | Y40: N/A | Z40: N/A | AA40: Yes
...
